2022-02-25 17:52:57 WARNING (SyncWorker_1) [homeassistant.loader] We found a custom integration hildebrandglow_dcc which has not been tested by Home Assistant. This component might cause stability problems, be sure to disable it if you experience issues with Home Assistant
2022-02-25 17:52:57 WARNING (SyncWorker_0) [homeassistant.loader] We found a custom integration nodered which has not been tested by Home Assistant. This component might cause stability problems, be sure to disable it if you experience issues with Home Assistant
2022-02-25 17:53:07 WARNING (MainThread) [hass_nabucasa.cloud_api] Fetched https://alexa-api.nabucasa.com/access_token (400)
2022-02-25 17:53:09 ERROR (MainThread) [homeassistant.components.mqtt] Failed to connect to MQTT server due to exception: timed out
2022-02-25 17:53:12 WARNING (MainThread) [hass_nabucasa.cloud_api] Fetched https://alexa-api.nabucasa.com/access_token (400)
2022-02-25 17:53:13 WARNING (MainThread) [hass_nabucasa.cloud_api] Fetched https://alexa-api.nabucasa.com/access_token (400)
2022-02-25 17:53:15 ERROR (MainThread) [homeassistant] Error doing job: Task exception was never retrieved
Traceback (most recent call last):
  File "/usr/src/homeassistant/homeassistant/components/cloud/alexa_config.py", line 364, in _handle_entity_registry_updated
    await self._sync_helper(to_update, to_remove)
  File "/usr/src/homeassistant/homeassistant/components/cloud/alexa_config.py", line 308, in _sync_helper
    await self.async_get_access_token()
  File "/usr/src/homeassistant/homeassistant/components/cloud/alexa_config.py", line 170, in async_get_access_token
    raise alexa_errors.RequireRelink
homeassistant.components.alexa.errors.RequireRelink
2022-02-25 17:53:15 ERROR (MainThread) [homeassistant] Error doing job: Task exception was never retrieved
Traceback (most recent call last):
  File "/usr/src/homeassistant/homeassistant/components/cloud/alexa_config.py", line 364, in _handle_entity_registry_updated
    await self._sync_helper(to_update, to_remove)
  File "/usr/src/homeassistant/homeassistant/components/cloud/alexa_config.py", line 308, in _sync_helper
    await self.async_get_access_token()
  File "/usr/src/homeassistant/homeassistant/components/cloud/alexa_config.py", line 170, in async_get_access_token
    raise alexa_errors.RequireRelink
homeassistant.components.alexa.errors.RequireRelink
2022-02-25 17:53:37 WARNING (MainThread) [homeassistant.helpers.service] Unable to find referenced entities script.doorbell
2022-02-25 17:53:38 ERROR (Thread-7) [homeassistant.components.cast.media_player] Failed to cast media https://p1f99kffoh1udmt972bc2sysd40xlbeb.ui.nabu.casa/media/local/Doorbell-1.mp3?authSig=eyJ0eXAiOiJKV1QiLCJhbGciOiJIUzI1NiJ9.eyJpc3MiOiI2MGRkNTZjZTlkMDc0NjU0YjYwZDdmOGQ5NDYwMzUzNCIsInBhdGgiOiIvbWVkaWEvbG9jYWwvRG9vcmJlbGwtMS5tcDMiLCJpYXQiOjE2NDU4MTE2MTcsImV4cCI6MTY0NTg5ODAxN30.AmvbedNWyiEqeNDwmwxggrD56u8zk8i1wCwRKI4yW9g from external_url (https://p1f99kffoh1udmt972bc2sysd40xlbeb.ui.nabu.casa). Please make sure the URL is: Reachable from the cast device and either a publicly resolvable hostname or an IP address
2022-02-25 17:53:38 ERROR (Thread-6) [homeassistant.components.cast.media_player] Failed to cast media https://p1f99kffoh1udmt972bc2sysd40xlbeb.ui.nabu.casa/media/local/Doorbell-1.mp3?authSig=eyJ0eXAiOiJKV1QiLCJhbGciOiJIUzI1NiJ9.eyJpc3MiOiI2MGRkNTZjZTlkMDc0NjU0YjYwZDdmOGQ5NDYwMzUzNCIsInBhdGgiOiIvbWVkaWEvbG9jYWwvRG9vcmJlbGwtMS5tcDMiLCJpYXQiOjE2NDU4MTE2MTcsImV4cCI6MTY0NTg5ODAxN30.AmvbedNWyiEqeNDwmwxggrD56u8zk8i1wCwRKI4yW9g from external_url (https://p1f99kffoh1udmt972bc2sysd40xlbeb.ui.nabu.casa). Please make sure the URL is: Reachable from the cast device and either a publicly resolvable hostname or an IP address
2022-02-25 17:53:58 WARNING (MainThread) [homeassistant.helpers.service] Unable to find referenced entities script.doorbell
2022-02-25 17:53:58 ERROR (Thread-7) [homeassistant.components.cast.media_player] Failed to cast media https://p1f99kffoh1udmt972bc2sysd40xlbeb.ui.nabu.casa/media/local/Doorbell-1.mp3?authSig=eyJ0eXAiOiJKV1QiLCJhbGciOiJIUzI1NiJ9.eyJpc3MiOiI2MGRkNTZjZTlkMDc0NjU0YjYwZDdmOGQ5NDYwMzUzNCIsInBhdGgiOiIvbWVkaWEvbG9jYWwvRG9vcmJlbGwtMS5tcDMiLCJpYXQiOjE2NDU4MTE2MzgsImV4cCI6MTY0NTg5ODAzOH0.wjLtaXzspqC5e2EZ2SFreK7q8HZd8QUVKKJk-4KelI4 from external_url (https://p1f99kffoh1udmt972bc2sysd40xlbeb.ui.nabu.casa). Please make sure the URL is: Reachable from the cast device and either a publicly resolvable hostname or an IP address
2022-02-25 17:53:58 ERROR (Thread-6) [homeassistant.components.cast.media_player] Failed to cast media https://p1f99kffoh1udmt972bc2sysd40xlbeb.ui.nabu.casa/media/local/Doorbell-1.mp3?authSig=eyJ0eXAiOiJKV1QiLCJhbGciOiJIUzI1NiJ9.eyJpc3MiOiI2MGRkNTZjZTlkMDc0NjU0YjYwZDdmOGQ5NDYwMzUzNCIsInBhdGgiOiIvbWVkaWEvbG9jYWwvRG9vcmJlbGwtMS5tcDMiLCJpYXQiOjE2NDU4MTE2MzgsImV4cCI6MTY0NTg5ODAzOH0.wjLtaXzspqC5e2EZ2SFreK7q8HZd8QUVKKJk-4KelI4 from external_url (https://p1f99kffoh1udmt972bc2sysd40xlbeb.ui.nabu.casa). Please make sure the URL is: Reachable from the cast device and either a publicly resolvable hostname or an IP address
2022-02-25 17:53:58 ERROR (Thread-7) [homeassistant.components.cast.media_player] Failed to cast media https://p1f99kffoh1udmt972bc2sysd40xlbeb.ui.nabu.casa/media/local/Doorbell-1.mp3?authSig=eyJ0eXAiOiJKV1QiLCJhbGciOiJIUzI1NiJ9.eyJpc3MiOiI2MGRkNTZjZTlkMDc0NjU0YjYwZDdmOGQ5NDYwMzUzNCIsInBhdGgiOiIvbWVkaWEvbG9jYWwvRG9vcmJlbGwtMS5tcDMiLCJpYXQiOjE2NDU4MTE2MzgsImV4cCI6MTY0NTg5ODAzOH0.wjLtaXzspqC5e2EZ2SFreK7q8HZd8QUVKKJk-4KelI4 from external_url (https://p1f99kffoh1udmt972bc2sysd40xlbeb.ui.nabu.casa). Please make sure the URL is: Reachable from the cast device and either a publicly resolvable hostname or an IP address
2022-02-25 17:53:59 ERROR (Thread-6) [homeassistant.components.cast.media_player] Failed to cast media https://p1f99kffoh1udmt972bc2sysd40xlbeb.ui.nabu.casa/media/local/Doorbell-1.mp3?authSig=eyJ0eXAiOiJKV1QiLCJhbGciOiJIUzI1NiJ9.eyJpc3MiOiI2MGRkNTZjZTlkMDc0NjU0YjYwZDdmOGQ5NDYwMzUzNCIsInBhdGgiOiIvbWVkaWEvbG9jYWwvRG9vcmJlbGwtMS5tcDMiLCJpYXQiOjE2NDU4MTE2MzgsImV4cCI6MTY0NTg5ODAzOH0.wjLtaXzspqC5e2EZ2SFreK7q8HZd8QUVKKJk-4KelI4 from external_url (https://p1f99kffoh1udmt972bc2sysd40xlbeb.ui.nabu.casa). Please make sure the URL is: Reachable from the cast device and either a publicly resolvable hostname or an IP address
2022-02-25 17:56:12 WARNING (MainThread) [homeassistant.helpers.service] Unable to find referenced entities script.doorbell
2022-02-25 17:56:12 ERROR (Thread-6) [homeassistant.components.cast.media_player] Failed to cast media https://p1f99kffoh1udmt972bc2sysd40xlbeb.ui.nabu.casa/media/local/doorbell-1.mp3?authSig=eyJ0eXAiOiJKV1QiLCJhbGciOiJIUzI1NiJ9.eyJpc3MiOiI2MGRkNTZjZTlkMDc0NjU0YjYwZDdmOGQ5NDYwMzUzNCIsInBhdGgiOiIvbWVkaWEvbG9jYWwvZG9vcmJlbGwtMS5tcDMiLCJpYXQiOjE2NDU4MTE3NzIsImV4cCI6MTY0NTg5ODE3Mn0.cxrQOFfagsOjPP9p1FaevobGYn0RmK8EVrjfKr9kPgE from external_url (https://p1f99kffoh1udmt972bc2sysd40xlbeb.ui.nabu.casa). Please make sure the URL is: Reachable from the cast device and either a publicly resolvable hostname or an IP address
2022-02-25 17:56:12 ERROR (Thread-7) [homeassistant.components.cast.media_player] Failed to cast media https://p1f99kffoh1udmt972bc2sysd40xlbeb.ui.nabu.casa/media/local/doorbell-1.mp3?authSig=eyJ0eXAiOiJKV1QiLCJhbGciOiJIUzI1NiJ9.eyJpc3MiOiI2MGRkNTZjZTlkMDc0NjU0YjYwZDdmOGQ5NDYwMzUzNCIsInBhdGgiOiIvbWVkaWEvbG9jYWwvZG9vcmJlbGwtMS5tcDMiLCJpYXQiOjE2NDU4MTE3NzIsImV4cCI6MTY0NTg5ODE3Mn0.cxrQOFfagsOjPP9p1FaevobGYn0RmK8EVrjfKr9kPgE from external_url (https://p1f99kffoh1udmt972bc2sysd40xlbeb.ui.nabu.casa). Please make sure the URL is: Reachable from the cast device and either a publicly resolvable hostname or an IP address
2022-02-25 17:57:44 WARNING (MainThread) [homeassistant.helpers.service] Unable to find referenced entities script.doorbell
2022-02-25 17:58:49 WARNING (MainThread) [homeassistant.helpers.service] Unable to find referenced entities script.doorbell
2022-02-25 19:05:05 ERROR (MainThread) [homeassistant.components.shelly] Error fetching Forest room Sensor data: Sleeping device did not update within 3600 seconds interval
2022-02-25 19:23:12 WARNING (MainThread) [homeassistant.helpers.service] Unable to find referenced entities script.doorbell
2022-02-25 23:30:13 WARNING (Thread-7) [pychromecast.socket_client] [office speaker(192.168.50.76):8009] Heartbeat timeout, resetting connection
2022-02-25 23:30:43 ERROR (Thread-7) [pychromecast.socket_client] [office speaker(192.168.50.76):8009] Failed to connect to service ServiceInfo(type='host', data=('192.168.50.76', 8009)), retrying in 5.0s
2022-02-26 01:25:46 ERROR (SyncWorker_0) [pyicloud.base] Authentication required for Account. (421)
2022-02-26 02:48:15 WARNING (Thread-6) [pychromecast.socket_client] [Living room speaker(192.168.50.52):8009] Heartbeat timeout, resetting connection
2022-02-26 02:48:18 ERROR (Thread-6) [pychromecast.socket_client] [Living room speaker(192.168.50.52):8009] Failed to connect to service ServiceInfo(type='host', data=('192.168.50.52', 8009)), retrying in 5.0s
2022-02-26 16:01:57 ERROR (SyncWorker_0) [pyicloud.base] Authentication required for Account. (421)
2022-02-26 17:57:48 WARNING (MainThread) [homeassistant.components.websocket_api.http.connection] [281473209028464] Disconnected: Did not receive auth message within 10 seconds
2022-02-26 18:14:58 ERROR (MainThread) [aioasuswrt.connection] Host timeout.
2022-02-26 23:30:16 WARNING (Thread-7) [pychromecast.socket_client] [office speaker(192.168.50.76):8009] Heartbeat timeout, resetting connection
2022-02-26 23:30:46 ERROR (Thread-7) [pychromecast.socket_client] [office speaker(192.168.50.76):8009] Failed to connect to service ServiceInfo(type='host', data=('192.168.50.76', 8009)), retrying in 5.0s
2022-02-27 04:51:29 WARNING (Thread-6) [pychromecast.socket_client] [Living room speaker(192.168.50.52):8009] Heartbeat timeout, resetting connection
2022-02-27 04:51:36 ERROR (Thread-6) [pychromecast.socket_client] [Living room speaker(192.168.50.52):8009] Failed to connect to service ServiceInfo(type='host', data=('192.168.50.52', 8009)), retrying in 5.0s
2022-02-27 06:38:23 ERROR (SyncWorker_0) [pyicloud.base] Authentication required for Account. (421)
2022-02-27 09:46:49 WARNING (MainThread) [homeassistant.helpers.service] Unable to find referenced entities script.doorbell
2022-02-27 09:52:33 ERROR (SyncWorker_1) [spotipy.client] HTTP Error for PUT to https://api.spotify.com/v1/me/player/shuffle?state=true with Params: {} returned 403 due to Restricted device
2022-02-27 09:52:52 ERROR (SyncWorker_1) [spotipy.client] HTTP Error for PUT to https://api.spotify.com/v1/me/player/play with Params: {} returned 403 due to Restricted device
2022-02-27 09:52:54 ERROR (SyncWorker_8) [spotipy.client] HTTP Error for PUT to https://api.spotify.com/v1/me/player/play with Params: {} returned 403 due to Restricted device
2022-02-27 14:34:14 WARNING (MainThread) [homeassistant.helpers.service] Unable to find referenced entities script.doorbell
2022-02-27 15:12:31 ERROR (MainThread) [aioasuswrt.connection] Host timeout.
2022-02-27 17:40:10 WARNING (Recorder) [homeassistant.components.sensor.recorder] Entity sensor.gas_consumption_today from integration hildebrandglow_dcc has state class total_increasing, but its state is not strictly increasing. Triggered by state 56.468 (56.612) with last_updated set to 2022-02-27T17:35:07.825979+00:00. Please report it to the custom component author.
2022-02-27 17:40:10 WARNING (Recorder) [homeassistant.components.sensor.recorder] Entity sensor.gas_consumption_year from integration hildebrandglow_dcc has state class total_increasing, but its state is not strictly increasing. Triggered by state 4930.315 (4930.46) with last_updated set to 2022-02-27T17:35:07.802462+00:00. Please report it to the custom component author.
2022-02-27 17:40:10 WARNING (Recorder) [homeassistant.components.sensor.recorder] Entity sensor.gas_cost_today from integration hildebrandglow_dcc has state class total_increasing, but its state is not strictly increasing. Triggered by state 4.76 (4.78) with last_updated set to 2022-02-27T17:35:07.925665+00:00. Please report it to the custom component author.
2022-02-27 21:13:06 ERROR (SyncWorker_3) [pyicloud.base] Authentication required for Account. (421)
2022-02-27 21:43:10 ERROR (SyncWorker_3) [pyicloud.base] Authentication required for Account. (421)
2022-02-27 23:31:21 WARNING (Thread-7) [pychromecast.socket_client] [office speaker(192.168.50.76):8009] Heartbeat timeout, resetting connection
2022-02-27 23:31:51 ERROR (Thread-7) [pychromecast.socket_client] [office speaker(192.168.50.76):8009] Failed to connect to service ServiceInfo(type='host', data=('192.168.50.76', 8009)), retrying in 5.0s
2022-02-28 02:23:27 WARNING (Thread-6) [pychromecast.socket_client] [Living room speaker(192.168.50.52):8009] Heartbeat timeout, resetting connection
2022-02-28 02:23:42 ERROR (Thread-6) [pychromecast.socket_client] [Living room speaker(192.168.50.52):8009] Failed to connect to service ServiceInfo(type='host', data=('192.168.50.52', 8009)), retrying in 5.0s
2022-02-28 07:51:32 ERROR (SyncWorker_1) [pyicloud.base] Authentication required for Account. (421)
2022-02-28 07:51:51 WARNING (SyncWorker_5) [pyicloud.base.http] Failed to parse response with JSON mimetype
2022-02-28 07:51:57 WARNING (MainThread) [hass_nabucasa.cloud_api] Fetched https://alexa-api.nabucasa.com/access_token (400)
2022-02-28 07:51:57 ERROR (MainThread) [homeassistant] Error doing job: Task exception was never retrieved
Traceback (most recent call last):
  File "/usr/src/homeassistant/homeassistant/components/cloud/alexa_config.py", line 364, in _handle_entity_registry_updated
    await self._sync_helper(to_update, to_remove)
  File "/usr/src/homeassistant/homeassistant/components/cloud/alexa_config.py", line 308, in _sync_helper
    await self.async_get_access_token()
  File "/usr/src/homeassistant/homeassistant/components/cloud/alexa_config.py", line 170, in async_get_access_token
    raise alexa_errors.RequireRelink
homeassistant.components.alexa.errors.RequireRelink
2022-02-28 07:51:58 WARNING (MainThread) [hass_nabucasa.cloud_api] Fetched https://alexa-api.nabucasa.com/access_token (400)
2022-02-28 07:51:58 ERROR (MainThread) [homeassistant] Error doing job: Task exception was never retrieved
Traceback (most recent call last):
  File "/usr/src/homeassistant/homeassistant/components/cloud/alexa_config.py", line 364, in _handle_entity_registry_updated
    await self._sync_helper(to_update, to_remove)
  File "/usr/src/homeassistant/homeassistant/components/cloud/alexa_config.py", line 308, in _sync_helper
    await self.async_get_access_token()
  File "/usr/src/homeassistant/homeassistant/components/cloud/alexa_config.py", line 170, in async_get_access_token
    raise alexa_errors.RequireRelink
homeassistant.components.alexa.errors.RequireRelink
2022-02-28 07:51:58 WARNING (MainThread) [hass_nabucasa.cloud_api] Fetched https://alexa-api.nabucasa.com/access_token (400)
2022-02-28 07:51:58 ERROR (MainThread) [homeassistant] Error doing job: Task exception was never retrieved
Traceback (most recent call last):
  File "/usr/src/homeassistant/homeassistant/components/cloud/alexa_config.py", line 364, in _handle_entity_registry_updated
    await self._sync_helper(to_update, to_remove)
  File "/usr/src/homeassistant/homeassistant/components/cloud/alexa_config.py", line 308, in _sync_helper
    await self.async_get_access_token()
  File "/usr/src/homeassistant/homeassistant/components/cloud/alexa_config.py", line 170, in async_get_access_token
    raise alexa_errors.RequireRelink
homeassistant.components.alexa.errors.RequireRelink
2022-02-28 07:51:58 WARNING (MainThread) [hass_nabucasa.cloud_api] Fetched https://alexa-api.nabucasa.com/access_token (400)
2022-02-28 07:51:58 ERROR (MainThread) [homeassistant] Error doing job: Task exception was never retrieved
Traceback (most recent call last):
  File "/usr/src/homeassistant/homeassistant/components/cloud/alexa_config.py", line 364, in _handle_entity_registry_updated
    await self._sync_helper(to_update, to_remove)
  File "/usr/src/homeassistant/homeassistant/components/cloud/alexa_config.py", line 308, in _sync_helper
    await self.async_get_access_token()
  File "/usr/src/homeassistant/homeassistant/components/cloud/alexa_config.py", line 170, in async_get_access_token
    raise alexa_errors.RequireRelink
homeassistant.components.alexa.errors.RequireRelink
2022-02-28 07:52:43 WARNING (MainThread) [hass_nabucasa.cloud_api] Fetched https://alexa-api.nabucasa.com/access_token (400)
2022-02-28 07:52:43 ERROR (MainThread) [homeassistant] Error doing job: Task exception was never retrieved
Traceback (most recent call last):
  File "/usr/src/homeassistant/homeassistant/components/cloud/alexa_config.py", line 364, in _handle_entity_registry_updated
    await self._sync_helper(to_update, to_remove)
  File "/usr/src/homeassistant/homeassistant/components/cloud/alexa_config.py", line 308, in _sync_helper
    await self.async_get_access_token()
  File "/usr/src/homeassistant/homeassistant/components/cloud/alexa_config.py", line 170, in async_get_access_token
    raise alexa_errors.RequireRelink
homeassistant.components.alexa.errors.RequireRelink
2022-02-28 07:52:43 WARNING (MainThread) [hass_nabucasa.cloud_api] Fetched https://alexa-api.nabucasa.com/access_token (400)
2022-02-28 07:52:43 ERROR (MainThread) [homeassistant] Error doing job: Task exception was never retrieved
Traceback (most recent call last):
  File "/usr/src/homeassistant/homeassistant/components/cloud/alexa_config.py", line 364, in _handle_entity_registry_updated
    await self._sync_helper(to_update, to_remove)
  File "/usr/src/homeassistant/homeassistant/components/cloud/alexa_config.py", line 308, in _sync_helper
    await self.async_get_access_token()
  File "/usr/src/homeassistant/homeassistant/components/cloud/alexa_config.py", line 170, in async_get_access_token
    raise alexa_errors.RequireRelink
homeassistant.components.alexa.errors.RequireRelink
2022-02-28 08:52:24 ERROR (MainThread) [homeassistant.components.device_tracker] Platform icloud does not generate unique IDs. ID ad0zRRa4saj3JdxQEgCSAYDfWq8Hbz3Oi3jk2sUzm253tox7izS2U+HYVNSUzmWV already exists - ignoring device_tracker.eamonns_iphone
2022-02-28 08:52:24 ERROR (MainThread) [homeassistant.components.sensor] Platform icloud does not generate unique IDs. ID ad0zRRa4saj3JdxQEgCSAYDfWq8Hbz3Oi3jk2sUzm253tox7izS2U+HYVNSUzmWV_battery already exists - ignoring sensor.eamonns_iphone_battery_state
2022-02-28 15:18:20 WARNING (MainThread) [homeassistant.components.cloud.google_config] Error reporting state - 5: Requested entity was not found.
2022-02-28 15:24:15 ERROR (SyncWorker_2) [pyicloud.base] Authentication required for Account. (421)
2022-02-28 15:24:27 ERROR (SyncWorker_5) [pyicloud.base] Authentication required for Account. (421)
2022-02-28 15:52:15 ERROR (Thread-7) [homeassistant.components.cast.media_player] Failed to cast media https://stream.radioparadise.com/aac-128. Please make sure the URL is: Reachable from the cast device and either a publicly resolvable hostname or an IP address
2022-02-28 15:53:26 ERROR (Thread-7) [homeassistant.components.cast.media_player] Failed to cast media https://www.bbc.co.uk/sounds/play/live:bbc_radio_fourfm. Please make sure the URL is: Reachable from the cast device and either a publicly resolvable hostname or an IP address
2022-02-28 15:53:26 ERROR (Thread-7) [homeassistant.components.cast.media_player] Failed to cast media https://www.bbc.co.uk/sounds/play/live:bbc_radio_fourfm. Please make sure the URL is: Reachable from the cast device and either a publicly resolvable hostname or an IP address
2022-02-28 15:53:33 ERROR (Thread-7) [homeassistant.components.cast.media_player] Failed to cast media https://www.bbc.co.uk/sounds/play/live:bbc_radio_fourfm. Please make sure the URL is: Reachable from the cast device and either a publicly resolvable hostname or an IP address
2022-02-28 15:53:34 ERROR (Thread-7) [homeassistant.components.cast.media_player] Failed to cast media https://www.bbc.co.uk/sounds/play/live:bbc_radio_fourfm. Please make sure the URL is: Reachable from the cast device and either a publicly resolvable hostname or an IP address
2022-02-28 16:51:59 WARNING (MainThread) [homeassistant.components.hue.bridge.light] Device Theresa’s bedside lamp changed state while reported as disconnected. This might be an indicator that routing is not working for this device or the device is having connectivity issues. You can disable availability reporting for this device in the Hue options. Device details: innr - On/Off plug (SP 222) fw: 2.1
2022-02-28 18:29:27 WARNING (MainThread) [hass_nabucasa.cloud_api] Fetched https://alexa-api.nabucasa.com/access_token (400)
2022-02-28 18:29:27 ERROR (MainThread) [homeassistant] Error doing job: Task exception was never retrieved
Traceback (most recent call last):
  File "/usr/src/homeassistant/homeassistant/components/cloud/alexa_config.py", line 364, in _handle_entity_registry_updated
    await self._sync_helper(to_update, to_remove)
  File "/usr/src/homeassistant/homeassistant/components/cloud/alexa_config.py", line 308, in _sync_helper
    await self.async_get_access_token()
  File "/usr/src/homeassistant/homeassistant/components/cloud/alexa_config.py", line 170, in async_get_access_token
    raise alexa_errors.RequireRelink
homeassistant.components.alexa.errors.RequireRelink
2022-02-28 22:26:35 ERROR (SyncWorker_6) [pyicloud.base] Authentication required for Account. (421)
2022-02-28 22:56:31 ERROR (SyncWorker_2) [pyicloud.base] Authentication required for Account. (421)
2022-02-28 23:30:20 WARNING (Thread-7) [pychromecast.socket_client] [office speaker(192.168.50.76):8009] Heartbeat timeout, resetting connection
2022-02-28 23:30:50 ERROR (Thread-7) [pychromecast.socket_client] [office speaker(192.168.50.76):8009] Failed to connect to service ServiceInfo(type='host', data=('192.168.50.76', 8009)), retrying in 5.0s
2022-03-01 00:27:01 WARNING (MainThread) [homeassistant.components.websocket_api.http.connection] [281473184448576] Disconnected: Did not receive auth message within 10 seconds
2022-03-01 04:59:45 WARNING (Thread-6) [pychromecast.socket_client] [Living room speaker(192.168.50.52):8009] Heartbeat timeout, resetting connection
2022-03-01 04:59:52 ERROR (Thread-6) [pychromecast.socket_client] [Living room speaker(192.168.50.52):8009] Failed to connect to service ServiceInfo(type='host', data=('192.168.50.52', 8009)), retrying in 5.0s
2022-03-01 05:58:03 ERROR (SyncWorker_8) [pyicloud.base] Authentication required for Account. (421)
2022-03-01 05:58:11 ERROR (SyncWorker_7) [pyicloud.base] Authentication required for Account. (421)
2022-03-01 12:59:57 ERROR (SyncWorker_7) [pyicloud.base] Authentication required for Account. (421)
2022-03-01 13:29:54 ERROR (SyncWorker_3) [pyicloud.base] Authentication required for Account. (421)
2022-03-01 20:31:29 ERROR (SyncWorker_3) [pyicloud.base] Authentication required for Account. (421)
2022-03-01 20:31:32 ERROR (SyncWorker_0) [pyicloud.base] Authentication required for Account. (421)
2022-03-01 23:30:20 WARNING (Thread-7) [pychromecast.socket_client] [office speaker(192.168.50.76):8009] Heartbeat timeout, resetting connection
2022-03-01 23:30:38 ERROR (Thread-7) [pychromecast.socket_client] [office speaker(192.168.50.76):8009] Failed to connect to service ServiceInfo(type='host', data=('192.168.50.76', 8009)), retrying in 5.0s
2022-03-02 00:03:06 ERROR (MainThread) [hass_nabucasa.remote] Timeout connecting to snitun server
2022-03-02 03:33:11 ERROR (SyncWorker_1) [pyicloud.base] Authentication required for Account. (421)
2022-03-02 04:03:19 ERROR (SyncWorker_1) [pyicloud.base] Authentication required for Account. (421)
2022-03-02 04:32:54 WARNING (Thread-6) [pychromecast.socket_client] [Living room speaker(192.168.50.52):8009] Heartbeat timeout, resetting connection
2022-03-02 04:33:01 ERROR (Thread-6) [pychromecast.socket_client] [Living room speaker(192.168.50.52):8009] Failed to connect to service ServiceInfo(type='host', data=('192.168.50.52', 8009)), retrying in 5.0s
2022-03-02 11:05:09 ERROR (SyncWorker_1) [pyicloud.base] Authentication required for Account. (421)
2022-03-02 11:35:05 ERROR (SyncWorker_7) [pyicloud.base] Authentication required for Account. (421)
2022-03-02 17:27:05 ERROR (SyncWorker_8) [spotipy.client] HTTP Error for PUT to https://api.spotify.com/v1/me/player/shuffle?state=true with Params: {} returned 403 due to Restricted device
2022-03-02 18:36:38 ERROR (SyncWorker_7) [pyicloud.base] Authentication required for Account. (421)
2022-03-02 18:36:48 ERROR (SyncWorker_9) [pyicloud.base] Authentication required for Account. (421)
2022-03-02 20:33:47 WARNING (MainThread) [homeassistant.helpers.service] Unable to find referenced entities switch.mantle_lights
2022-03-02 23:30:14 WARNING (Thread-7) [pychromecast.socket_client] [office speaker(192.168.50.76):8009] Heartbeat timeout, resetting connection
2022-03-02 23:30:45 ERROR (Thread-7) [pychromecast.socket_client] [office speaker(192.168.50.76):8009] Failed to connect to service ServiceInfo(type='host', data=('192.168.50.76', 8009)), retrying in 5.0s
2022-03-03 01:38:53 ERROR (SyncWorker_1) [pyicloud.base] Authentication required for Account. (421)
2022-03-03 02:08:58 ERROR (SyncWorker_6) [pyicloud.base] Authentication required for Account. (421)
2022-03-03 02:40:03 WARNING (Thread-6) [pychromecast.socket_client] [Living room speaker(192.168.50.52):8009] Heartbeat timeout, resetting connection
2022-03-03 02:40:10 ERROR (Thread-6) [pychromecast.socket_client] [Living room speaker(192.168.50.52):8009] Failed to connect to service ServiceInfo(type='host', data=('192.168.50.52', 8009)), retrying in 5.0s
2022-03-03 06:08:20 WARNING (SyncWorker_5) [urllib3.connectionpool] Retrying (Retry(total=9, connect=10, read=9, redirect=None, status=None)) after connection broken by 'ReadTimeoutError("HTTPConnectionPool(host='datapoint.metoffice.gov.uk', port=80): Read timed out. (read timeout=1)")': /public/data/val/wxfcs/all/json/3672?key=21202dde-c73e-4522-842b-4e57aaa68c45&res=3hourly
2022-03-03 08:40:02 ERROR (SyncWorker_5) [pyicloud.base] Authentication required for Account. (421)
2022-03-03 09:10:26 ERROR (SyncWorker_0) [pyicloud.base] Authentication required for Account. (421)
2022-03-03 15:44:44 ERROR (SyncWorker_3) [pyicloud.base] Authentication required for Account. (421)
2022-03-03 16:15:10 ERROR (SyncWorker_3) [pyicloud.base] Authentication required for Account. (421)
2022-03-03 22:47:07 ERROR (SyncWorker_5) [pyicloud.base] Authentication required for Account. (421)
2022-03-03 23:17:30 ERROR (SyncWorker_3) [pyicloud.base] Authentication required for Account. (421)
2022-03-03 23:30:14 WARNING (Thread-7) [pychromecast.socket_client] [office speaker(192.168.50.76):8009] Heartbeat timeout, resetting connection
2022-03-03 23:30:22 ERROR (MainThread) [homeassistant.core] Error executing service: <ServiceCall switch.turn_off (c:bf56d4aaffe0bcbdfe6014812a7d8df4): entity_id=['switch.ocean_room_power']>
Traceback (most recent call last):
  File "/usr/src/homeassistant/homeassistant/core.py", line 1648, in catch_exceptions
    await coro_or_task
  File "/usr/src/homeassistant/homeassistant/core.py", line 1667, in _execute_service
    await cast(Callable[[ServiceCall], Awaitable[None]], handler.job.target)(
  File "/usr/src/homeassistant/homeassistant/helpers/entity_component.py", line 204, in handle_service
    await self.hass.helpers.service.entity_service_call(
  File "/usr/src/homeassistant/homeassistant/helpers/service.py", line 668, in entity_service_call
    future.result()  # pop exception if have
  File "/usr/src/homeassistant/homeassistant/helpers/entity.py", line 930, in async_request_call
    await coro
  File "/usr/src/homeassistant/homeassistant/helpers/service.py", line 705, in _handle_entity_call
    await result
  File "/usr/src/homeassistant/homeassistant/components/zwave_js/switch.py", line 83, in async_turn_off
    await self.info.node.async_set_value(self._target_value, False)
  File "/usr/local/lib/python3.9/site-packages/zwave_js_server/model/node.py", line 478, in async_set_value
    result = await self.async_send_command(
  File "/usr/local/lib/python3.9/site-packages/zwave_js_server/model/node.py", line 435, in async_send_command
    result = await self.client.async_send_command(message, **kwargs)
  File "/usr/local/lib/python3.9/site-packages/zwave_js_server/client.py", line 103, in async_send_command
    return await future
zwave_js_server.exceptions.FailedZWaveCommand: Z-Wave error 204: Failed to send the command after 3 attempts (Status NoAck) (ZW0204)
2022-03-03 23:30:44 ERROR (Thread-7) [pychromecast.socket_client] [office speaker(192.168.50.76):8009] Failed to connect to service ServiceInfo(type='host', data=('192.168.50.76', 8009)), retrying in 5.0s
2022-03-04 02:37:54 WARNING (Thread-6) [pychromecast.socket_client] [Living room speaker(192.168.50.52):8009] Heartbeat timeout, resetting connection
2022-03-04 02:38:01 ERROR (Thread-6) [pychromecast.socket_client] [Living room speaker(192.168.50.52):8009] Failed to connect to service ServiceInfo(type='host', data=('192.168.50.52', 8009)), retrying in 5.0s
2022-03-04 05:48:46 ERROR (SyncWorker_8) [pyicloud.base] Authentication required for Account. (421)
2022-03-04 06:48:43 ERROR (SyncWorker_9) [pyicloud.base] Authentication required for Account. (421)
2022-03-04 07:00:21 ERROR (MainThread) [homeassistant.core] Error executing service: <ServiceCall switch.turn_on (c:05dfa6a6f279c6425aa45d9c4e647bcd): entity_id=['switch.ocean_room_power']>
Traceback (most recent call last):
  File "/usr/src/homeassistant/homeassistant/core.py", line 1648, in catch_exceptions
    await coro_or_task
  File "/usr/src/homeassistant/homeassistant/core.py", line 1667, in _execute_service
    await cast(Callable[[ServiceCall], Awaitable[None]], handler.job.target)(
  File "/usr/src/homeassistant/homeassistant/helpers/entity_component.py", line 204, in handle_service
    await self.hass.helpers.service.entity_service_call(
  File "/usr/src/homeassistant/homeassistant/helpers/service.py", line 668, in entity_service_call
    future.result()  # pop exception if have
  File "/usr/src/homeassistant/homeassistant/helpers/entity.py", line 930, in async_request_call
    await coro
  File "/usr/src/homeassistant/homeassistant/helpers/service.py", line 705, in _handle_entity_call
    await result
  File "/usr/src/homeassistant/homeassistant/components/zwave_js/switch.py", line 78, in async_turn_on
    await self.info.node.async_set_value(self._target_value, True)
  File "/usr/local/lib/python3.9/site-packages/zwave_js_server/model/node.py", line 478, in async_set_value
    result = await self.async_send_command(
  File "/usr/local/lib/python3.9/site-packages/zwave_js_server/model/node.py", line 435, in async_send_command
    result = await self.client.async_send_command(message, **kwargs)
  File "/usr/local/lib/python3.9/site-packages/zwave_js_server/client.py", line 103, in async_send_command
    return await future
zwave_js_server.exceptions.FailedZWaveCommand: Z-Wave error 204: Failed to send the command after 3 attempts (Status NoAck) (ZW0204)
